Workbook

Sheet 说明
A1: 《A Gift for Ghost》声音需求表
A2: 来源：docs/script/02_dialogue.csv（定稿台词表）、01_beats.csv（玩法表）和当前已实现的玩法。旧的 04_media_assets.csv 配音清单已过期，以本表为准。段落用颜色区分：INTRO 灰、TUT 蓝、S1 绿、S2 橙、S3 紫、S4 红、PICK 黄。
A4: 数量汇总（自动统计）
A5: 配音：台词条数 | B5: =COUNTA('配音'!A2:A78)
A6: 配音：需要录制 | B6: =COUNTIF('配音'!G2:G78,"是")
A7: 其中 亲切的声音 | B7: =COUNTIFS('配音'!C2:C78,"亲切的声音",'配音'!G2:G78,"是")
A8: 其中 没有温度的声音（Agent） | B8: =COUNTIFS('配音'!C2:C78,"没有温度的声音",'配音'!G2:G78,"是")
A9: 配音：估算总时长（秒） | B9: =SUMIF('配音'!G2:G78,"是",'配音'!J2:J78)
A10: 音效：条目数 | B10: =COUNTA('音效'!A2:A59)
A11: 音效：文件数（含变体） | B11: =SUM('音效'!I2:I59)
A12: 其中 P0 条目（必须） | B12: =COUNTIF('音效'!J2:J59,"P0")
A13: 其中 P1 条目（应该有） | B13: =COUNTIF('音效'!J2:J59,"P1")
A14: 其中 P2 条目（有时间再做） | B14: =COUNTIF('音效'!J2:J59,"P2")
A15: 音乐与环境音：条目数 | B15: =COUNTA('音乐与环境音'!A2:A10)
A16: 视频音轨：条目数 | B16: =COUNTA('视频音轨'!A2:A4)
A18: 角色与声线
A19: 亲切的声音：温柔女声，显示在屏幕底部字幕。剧情上是治疗中心 / 关心你的人的声音，建议真人录。
A20: 没有温度的声音：机械女声，即 Agent，显示在左侧弹窗。可以用 TTS + 电子处理（轻微 bitcrush / 环形调制），全程保持同一种处理。
A22: 整体声音方向
A23: 主线是“从 Agent 代理的数字世界回到真实感官”：INTRO–S2 冷、电子、干净；S3 加入色彩和空间感；S4 每摘一只虫子更自然一档；PICK 以真实阳台环境声为主。
A24: 音乐建议做成同一主题的分层（stems），各阶段叠加或替换乐器，转场不用硬切。
A26: 交付规格
A27: 配音：WAV 48kHz 16bit 单声道，句首句尾各留 0.2s 空白，无背景音，文件名用“配音”表的文件名列。
A28: 音效：WAV 48kHz 16bit 单声道（标了立体声 / 3D 的除外），峰值 ≤ -3dB；有变体的命名 _01、_02……
A29: 音乐 / 环境音：OGG 或 WAV 48kHz 立体声，循环的需要无缝循环点。
A30: 优先级：P0 = demo 必须有；P1 = 应该有；P2 = 有时间再做。
A32: 待确认（策划）
... A36: 4. 视频音轨谁做：视频自带声音，还是音效老师按画面另做后合成？

Sheet 配音
A1: 文件名 | B1: 段落 | C1: 角色 | D1: 显示位置 | E1: 台词 | F1: 表演提示 | G1: 需要配音 | H1: 备注 | I1: 字数 | J1: 估算时长(s)
A2: VO_INTRO_001 | B2: INTRO | C2: 亲切的声音 | D2: 字幕 | E2: 嗨，你醒了。 | F2: 轻、近，像在耳边唤醒一个刚睡醒的人 | G2: 是 | I2: =LEN(E2) | J2: =ROUND(I2/$M$3+0.4,1) | L2: 估算参数
A3: VO_INTRO_002 | B3: INTRO | C3: 没有温度的声音 | D3: Agent弹窗 | E3: 神经连接已恢复。 | F3: 平稳、无情绪、语速均匀 | G3: 是 | I3: =LEN(E3) | J3: =ROUND(I3/$M$3+0.4,1) | L3: 语速（字/秒） | M3: 4.5
A4: VO_INTRO_003 | B4: INTRO | C4: 没有温度的声音 | D4: Agent弹窗 | E4: 检测到稳定的意识活动。 | F4: 平稳、无情绪、语速均匀 | G4: 是 | I4: =LEN(E4) | J4: =ROUND(I4/$M$3+0.4,1) | L4: 估算时长 = 字数 ÷ 语速 + 0.4s 首尾留白。蓝色数字可改。
A5: VO_INTRO_004 | B5: INTRO | C5: 没有温度的声音 | D5: Agent弹窗 | E5: 语言和运动通道尚未恢复。 | F5: 平稳、无情绪、语速均匀 | G5: 是 | I5: =LEN(E5) | J5: =ROUND(I5/$M$3+0.4,1)
A6: VO_INTRO_005 | B6: INTRO | C6: 亲切的声音 | D6: 字幕 | E6: 也许你没有意识到，你生活在这片虚无的黑暗中已经很久了。 | F6: 缓慢，带一点心疼 | G6: 是 | I6: =LEN(E6) | J6: =ROUND(I6/$M$3+0.4,1)
A7: VO_INTRO_006 | B7: INTRO | C7: 亲切的声音 | D7: 字幕 | E7: 如果你能听到我的声音，这里是认知贫化症候治疗中心。有很多人在关心你的状况。 | F7: 安抚、可信，像医护人员 | G7: 是 | I7: =LEN(E7) | J7: =ROUND(I7/$M$3+0.4,1)
A8: VO_INTRO_007 | B8: INTRO | C8: 亲切的声音 | D8: 字幕 | E8: ……不，这不是玩笑。你当然仍处在“现实”之中， | F8: 先停顿（……），轻轻否认，略带苦笑 | G8: 是 | I8: =LEN(E8) | J8: =ROUND(I8/$M$3+0.4,1)
A9: VO_INTRO_008 | B9: INTRO | C9: 亲切的声音 | D9: 字幕 | E9: 但由于你长久以来使用agent过度代理与现实世界信息交互，感官与神经机能出现了严重退化——也就是现在大流行的“认知贫化症”，大脑失去了重建真实世界的能力。我目前正在尝试通过脑机接口与你建立连接。 | F9: 解释性，语速平稳 | G9: 是 | H9: 较长，可按逗号分 2–3 个文件录 | I9: =LEN(E9) | J9: =ROUND(I9/$M$3+0.4,1)
A10: VO_INTRO_009 | B10: INTRO | C10: 亲切的声音 | D10: 字幕 | E10: ……检测到神经信号回应，很高兴知道你还在这里。我已经与你进行感知野同步——看来这里现在确实空空无一物，嗯？ | F10: 惊喜后松一口气，最后“嗯？”带点俏皮 | G10: 是 | I10: =LEN(E10) | J10: =ROUND(I10/$M$3+0.4,1)
A11: VO_INTRO_010 | B11: INTRO | C11: 亲切的声音 | D11: 字幕 | E11: 别担心，接下来我会逐步引导你，通过一系列简单的认知练习来恢复基本认知功能。 | F11: 鼓励 | G11: 是 | I11: =LEN(E11) | J11: =ROUND(I11/$M$3+0.4,1)
A12: VO_INTRO_011 | B12: INTRO | C12: 亲切的声音 | D12: 字幕 | E12: 让我们先从你目前能承受的认知负荷开始。 | F12: 温柔、亲近 | G12: 是 | I12: =LEN(E12) | J12: =ROUND(I12/$M$3+0.4,1)
A13: VO_TUT_002 | B13: TUT | C13: 亲切的声音 | D13: 字幕 | E13: 看到那个闪烁的方块了吗？这是一个被高度压缩过的信息单元，它代表着你现实世界生活中的一项具体事务，在这里都会显示为量化好的待处理任务。 | F13: 引导，像在指给对方看 | G13: 是 | I13: =LEN(E13) | J13: =ROUND(I13/$M$3+0.4,1)
A14: VO_TUT_003 | B14: TUT | C14: 亲切的声音 | D14: 字幕 | E14: 点击异常节点，即批准agent对其进行一次自动处理。 | F14: 清晰的操作说明 | G14: 是 | I14: =LEN(E14) | J14: =ROUND(I14/$M$3+0.4,1)
A15: VO_TUT_004 | B15: TUT | C15: 没有温度的声音 | D15: Agent弹窗 | E15: Mission Accomplished. 验收通过，日志已更新。 | F15: 平稳、无情绪、语速均匀 | G15: 是 | I15: =LEN(E15) | J15: =ROUND(I15/$M$3+0.4,1)
A16: VO_TUT_006 | B16: TUT | C16: 亲切的声音 | D16: 字幕 | E16: 基本上，这就是你现在每天全部的思维活动了。 | F16: 略带自嘲 / 无奈 | G16: 是 | I16: =LEN(E16) | J16: =ROUND(I16/$M$3+0.4,1)
A17: VO_TUT_007 | B17: TUT | C17: 亲切的声音 | D17: 字幕 | E17: 再来看看这个。 | F17: 轻快，转折 | G17: 是 | I17: =LEN(E17) | J17: =ROUND(I17/$M$3+0.4,1)
A18: VO_TUT_008 | B18: TUT | C18: 没有温度的声音 | D18: Agent弹窗 | E18: Mission Failed。重试超时，进程已离线。 | F18: 报错，平直 | G18: 是 | I18: =LEN(E18) | J18: =ROUND(I18/$M$3+0.4,1)
A19: VO_TUT_009 | B19: TUT | C19: 没有温度的声音 | D19: Agent弹窗 | E19: 问题分析……未找到；已提交错误报告并移入待审查异常序列。 | F19: 平稳、无情绪、语速均匀 | G19: 是 | I19: =LEN(E19) | J19: =ROUND(I19/$M$3+0.4,1)
A20: VO_TUT_010 | B20: TUT | C20: 亲切的声音 | D20: 字幕 | E20: 但总有一些时候，通用的逻辑与抽象经验解决不了问题。如果节点继续闪烁，就意味着异常仍在抛出。 | F20: 认真起来 | G20: 是 | I20: =LEN(E20) | J20: =ROUND(I20/$M$3+0.4,1)
A21: VO_TUT_011 | B21: TUT | C21: 亲切的声音 | D21: 字幕 | E21: 这便是需要你主动介入的时候了。用更原始的办法打捞更原始的信息；解决之道，往往就在其中。 | F21: 坚定、有一点期许 | G21: 是 | I21: =LEN(E21) | J21: =ROUND(I21/$M$3+0.4,1)
... A23: VO_TUT_013 | B23: TUT | C23: 亲切的声音 | D23: 字幕 | E23: 让我们来看看你走了多远。 | F23: 温柔、亲近 | G23: 是 | I23: =LEN(E23) | J23: =ROUND(I23/$M$3+0.4,1)
A24: VO_TUT_014 | B24: TUT | C24: 没有温度的声音 | D24: 右键详情 | E24: 维护单元07：稳定度下降 / 建议操作：补充资源 / 预计改善：+12% | F24: 平稳、无情绪、语速均匀 | G24: 否（建议） | H24: 右键详情框里的文字，建议不配音，只播 SFX_DETAIL_OPEN | I24: =LEN(E24) | J24: =ROUND(I24/$M$3+0.4,1)
A25: VO_TUT_015 | B25: TUT | C25: 亲切的声音 | D25: 字幕 | E25: 直观、清晰、安心……也有些令人感到茫然。 | F25: 先平静描述，到“茫然”时声音放低 | G25: 是 | I25: =LEN(E25) | J25: =ROUND(I25/$M$3+0.4,1)
A26: VO_TUT_016 | B26: TUT | C26: 亲切的声音 | D26: 字幕 | E26: 不过别着急，我今天正是为此而来。 | F26: 温暖、笃定 | G26: 是 | I26: =LEN(E26) | J26: =ROUND(I26/$M$3+0.4,1)
A27: VO_S1_001 | B27: S1 | C27: 亲切的声音 | D27: 字幕 | E27: 真实生活的“任务系统”随机而复杂，为了适应恢复感官后的信息处理速度，我们首先来做一个并行处理能力练习。 | F27: 温柔、亲近 | G27: 是 | I27: =LEN(E27) | J27: =ROUND(I27/$M$3+0.4,1)
A28: VO_S1_P01 | B28: S1 | C28: 没有温度的声音 | D28: Agent弹窗 | E28: 维护单元{01-99}：稳定度下降 / 建议操作：补充资源 / 预计改善：+{5-20}% | F28: 平稳、无情绪、语速均匀 | G28: 否（建议） | H28: 随机池，文本带随机数字，不适合配音；建议用 SFX_AGENT_DATA（数据念白电子音）代替 | I28: =LEN(E28) | J28: =ROUND(I28/$M$3+0.4,1)
A29: VO_S1_P02 | B29: S1 | C29: 没有温度的声音 | D29: Agent弹窗 | E29: 外部联系{01-99}：等待回应 / 建议操作：自动回复 / 关系风险：低 | F29: 平稳、无情绪、语速均匀 | G29: 否（建议） | H29: 随机池，文本带随机数字，不适合配音；建议用 SFX_AGENT_DATA（数据念白电子音）代替 | I29: =LEN(E29) | J29: =ROUND(I29/$M$3+0.4,1)
A30: VO_S1_P03 | B30: S1 | C30: 没有温度的声音 | D30: Agent弹窗 | E30: 日程节点{01-99}：时段冲突 / 建议操作：自动顺延 / 置信度：{70-98}% | F30: 平稳、无情绪、语速均匀 | G30: 否（建议） | H30: 随机池，文本带随机数字，不适合配音；建议用 SFX_AGENT_DATA（数据念白电子音）代替 | I30: =LEN(E30) | J30: =ROUND(I30/$M$3+0.4,1)
A31: VO_S1_P04 | B31: S1 | C31: 没有温度的声音 | D31: Agent弹窗 | E31: 营养摄入{01-99}：低于基准 / 建议操作：订购标准餐 / 预计改善：+{3-15}% | F31: 平稳、无情绪、语速均匀 | G31: 否（建议） | H31: 随机池，文本带随机数字，不适合配音；建议用 SFX_AGENT_DATA（数据念白电子音）代替 | I31: =LEN(E31) | J31: =ROUND(I31/$M$3+0.4,1)
A32: VO_S1_P05 | B32: S1 | C32: 没有温度的声音 | D32: Agent弹窗 | E32: 睡眠周期{01-99}：深睡不足 / 建议操作：调整提醒时段 / 风险：中 | F32: 平稳、无情绪、语速均匀 | G32: 否（建议） | H32: 随机池，文本带随机数字，不适合配音；建议用 SFX_AGENT_DATA（数据念白电子音）代替 | I32: =LEN(E32) | J32: =ROUND(I32/$M$3+0.4,1)
A33: VO_S1_P06 | B33: S1 | C33: 没有温度的声音 | D33: Agent弹窗 | E33: 社交请求{01-99}：未读 / 建议操作：模板回复 / 关系风险：低 / 置信度：{80-99}% | F33: 平稳、无情绪、语速均匀 | G33: 否（建议） | H33: 随机池，文本带随机数字，不适合配音；建议用 SFX_AGENT_DATA（数据念白电子音）代替 | I33: =LEN(E33) | J33: =ROUND(I33/$M$3+0.4,1)
A34: VO_S1_002 | B34: S1 | C34: 没有温度的声音 | D34: Agent弹窗 | E34: 核心项目：本周期进度落后 / 建议操作：提高执行强度 | F34: 警告提示，略重 | G34: 是 | I34: =LEN(E34) | J34: =ROUND(I34/$M$3+0.4,1)
A35: VO_S1_003 | B35: S1 | C35: 亲切的声音 | D35: 字幕 | E35: 看起来你已经恢复了最基本的信息处理能力，并且逐渐开始对这些没头没尾的离散信息感到困惑。 | F35: 欣慰中带一点关切 | G35: 是 | I35: =LEN(E35) | J35: =ROUND(I35/$M$3+0.4,1)
A36: VO_S1_004 | B36: S1 | C36: 亲切的声音 | D36: 字幕 | E36: 现在我们将开始重建信息节点之间的语义关系与概念地图。 | F36: 温柔、亲近 | G36: 是 | I36: =LEN(E36) | J36: =ROUND(I36/$M$3+0.4,1)
A37: VO_S1_005 | B37: S1 | C37: 没有温度的声音 | D37: Agent询问 | E37: 是否要进一步查看信息？ | F37: 平稳、无情绪、语速均匀 | G37: 是 | I37: =LEN(E37) | J37: =ROUND(I37/$M$3+0.4,1)
A38: VO_S2_001 | B38: S2 | C38: 没有温度的声音 | D38: Agent弹窗 | E38: 关联视图正在展开…… | F38: 平稳、无情绪、语速均匀 | G38: 是 | I38: =LEN(E38) | J38: =ROUND(I38/$M$3+0.4,1)
A39: VO_S2_002 | B39: S2 | C39: 没有温度的声音 | D39: Agent弹窗 | E39: 已在本概念层展开重新分析。扫描全局状态。 | F39: 平稳、无情绪、语速均匀 | G39: 是 | I39: =LEN(E39) | J39: =ROUND(I39/$M$3+0.4,1)
A40: VO_S2_003 | B40: S2 | C40: 没有温度的声音 | D40: Agent弹窗 | E40: 问题定位：远端生产系统增长缓滞，判断首要可能性为供给层资源供应不足。建议从支撑系统开始修复。 | F40: 平稳、无情绪、语速均匀 | G40: 是 | I40: =LEN(E40) | J40: =ROUND(I40/$M$3+0.4,1)
A41: VO_S2_004 | B41: S2 | C41: 亲切的声音 | D41: 字幕 | E41: 看来你的Agent在系统层面的架构设计上仍然有所短板。 | F41: 略带调侃 Agent | G41: 是 | I41: =LEN(E41) | J41: =ROUND(I41/$M$3+0.4,1)
...

Sheet 音效
A1: 编号 | B1: 段落 | C1: 类别 | D1: 名称 | E1: 触发时机 | F1: 声音描述 / 参考 | G1: 参考时长 | H1: 循环 | I1: 变体数 | J1: 优先级 | K1: 备注 / 待确认
A2: SFX_SUBTITLE_IN | B2: 通用 | C2: UI/对白 | D2: 字幕出现 | E2: 每句亲切的声音字幕出现 | F2: 很轻、温暖的提示 | G2: 0.2s | H2: 否 | I2: 1 | J2: P2 | K2: 有配音时可能不需要
A3: SFX_AGENT_POPUP | B3: 通用 | C3: UI/对白 | D3: Agent 弹窗出现 | E3: 每次左侧 Agent 弹窗出现 | F3: 冷感电子提示，和字幕音明显区分 | G3: 0.3s | H3: 否 | I3: 1 | J3: P0
A4: SFX_AGENT_TYPE | B4: 通用 | C4: UI/对白 | D4: Agent 文字输出 | E4: Agent 弹窗文字逐字出现时 | F4: 细碎的数据 / 打字声 | G4: 1–2s | H4: 是 | I4: 1 | J4: P2 | K4: 文字不是逐字出现就不需要
A5: SFX_AGENT_DATA | B5: S1 | C5: UI/对白 | D5: 数据念白 | E5: S1 点方块弹出随机任务时（代替随机池配音） | F5: 听不清内容的电子念白 / 压缩语音，像 Agent 在快速播报 | G5: 0.8–1.5s | H5: 否 | I5: 4 | J5: P1 | K5: 4 个变体随机播，避免重复
A6: SFX_ADVANCE | B6: 通用 | C6: UI/对白 | D6: 点击跳过对白 | E6: 点击空白处快进 | F6: 极轻的点击 | G6: 0.1s | H6: 否 | I6: 1 | J6: P2
A7: SFX_QUERY_OPEN | B7: 通用 | C7: UI/对白 | D7: Agent 询问弹窗出现 | E7: S1_005 / S2_009 / S3_011 | F7: 比普通弹窗更“正式”的提示，带等待感 | G7: 0.5s | H7: 否 | I7: 1 | J7: P1
A8: SFX_QUERY_WARN | B8: S3 | C8: UI/对白 | D8: 高风险警告 | E8: S3_011 “检测到高风险操作” | F8: 警报感但不刺耳（双音交替） | G8: 0.8s | H8: 否 | I8: 1 | J8: P1 | K8: 也可以和 QUERY_OPEN 合并
A9: SFX_YES_HOVER | B9: 通用 | C9: UI/对白 | D9: Yes 按钮悬停 | E9: 鼠标移到 Yes 上 | F9: 轻微的 tick | G9: 0.1s | H9: 否 | I9: 1 | J9: P2
A10: SFX_YES_CONFIRM | B10: 通用 | C10: UI/对白 | D10: 点击 Yes | E10: 点 Yes 进入下一关 | F10: 确认音，带一点“开启”的上行 | G10: 0.4s | H10: 否 | I10: 1 | J10: P0
A11: SFX_NODE_HOVER | B11: 通用 | C11: 交互 | D11: 节点悬停 | E11: 鼠标悬停到节点上 | F11: 极轻的电子 tick，可随机音高 | G11: 0.05–0.1s | H11: 否 | I11: 3 | J11: P2 | K11: 音量要很低，否则会吵
A12: SFX_DETAIL_OPEN | B12: 通用 | C12: 交互 | D12: 右键详情展开 | E12: 右键查看节点详情（TUT / S2 / S3） | F12: 扫描 / 展开声 | G12: 0.3s | H12: 否 | I12: 1 | J12: P0
A13: SFX_DETAIL_CLOSE | B13: 通用 | C13: 交互 | D13: 右键详情关闭 | E13: 详情框关闭 | F13: 展开声的反向，更短 | G13: 0.2s | H13: 否 | I13: 1 | J13: P2
A14: SFX_INTRO_LINK | B14: INTRO | C14: 演出 | D14: 神经连接恢复 | E14: INTRO_002 Agent 第一句 | F14: 系统上线 / 连接建立的电子音 | G14: 1s | H14: 否 | I14: 1 | J14: P2
A15: SFX_INTRO_WAKE | B15: INTRO | C15: 演出 | D15: 神经信号回应 | E15: INTRO_008 后玩家点击任意处 | F15: 心跳 / 神经脉冲般的低频“咚”，带一点亮起感 | G15: 1s | H15: 否 | I15: 1 | J15: P1 | K15: 玩家第一次操作，要有回应感
A16: SFX_BLOCK_PULSE | B16: TUT | C16: 交互 | D16: 方块呼吸闪烁 | E16: 方块从暗到亮循环（TUT、S1） | F16: 微弱的电子呼吸声，和闪烁同步 | G16: 1–2s | H16: 是 | I16: 1 | J16: P1 | K16: S1 多个方块同时亮时要压低或只给新亮起的
A17: SFX_TAP_AUTH | B17: TUT | C17: 交互 | D17: 点击授权 | E17: 左键点节点（授权 Agent 处理，TUT、S1） | F17: 短促确认音，偏电子 | G17: 0.2–0.4s | H17: 否 | I17: 3 | J17: P0 | K17: S1 连点很频繁，做 3 个音高变体
A18: SFX_AGENT_PROCESS | B18: TUT | C18: 交互 | D18: Agent 处理中 | E18: 点击后到出结果之间 | F18: 短促的处理 / 运算声 | G18: 0.3–0.6s | H18: 否 | I18: 1 | J18: P2
A19: SFX_TASK_SUCCESS | B19: TUT | C19: 反馈 | D19: Mission Accomplished | E19: TUT_004 简单问题解决 | F19: 干净、机械的完成音 | G19: 0.5s | H19: 否 | I19: 1 | J19: P0
A20: SFX_TASK_FAIL | B20: TUT | C20: 反馈 | D20: Mission Failed | E20: TUT_008 困难问题失败 | F20: 报错，带“断开 / 离线”的下行 | G20: 0.6s | H20: 否 | I20: 1 | J20: P0
A21: SFX_BLOCK_DIM | B21: TUT | C21: 反馈 | D21: 方块变暗 | E21: 方块被处理后变暗（TUT、S1） | F21: 下行的柔和音 | G21: 0.3–0.6s | H21: 否 | I21: 2 | J21: P1
A22: SFX_BLOCK_RELIGHT | B22: TUT | C22: 反馈 | D22: 方块重新亮起 | E22: 失败后 2–3s 再闪 / S1 处理过的方块又亮 | F22: 略带不安的上行 | G22: 0.3s | H22: 否 | I22: 1 | J22: P1
A23: SFX_TUT_TO_MATRIX | B23: TUT | C23: 转场 | D23: 方块融入矩阵 | E23: TUT_016 后方块后退缩小、其余方块渐显 | F23: 远去的 whoosh + 大量小方块依次亮起 | G23: 2–3s | H23: 否 | I23: 1 | J23: P1 | K23: 转场时长待定
A24: SFX_S1_WARN | B24: S1 | C24: 反馈 | D24: 进度落后警告 | E24: S1_002 通关时 | F24: 低沉的系统警告 | G24: 0.8s | H24: 否 | I24: 1 | J24: P2
A25: SFX_MORPH | B25: 转场 | C25: 转场 | D25: 植株变形 | E25: 每次进入新阶段，节点重组 | F25: 数据重组 / 粒子聚合 | G25: 1.5–3s | H25: 否 | I25: 4 | J25: P0 | K25: 4 次转场各一个变体（S1→S2、S2→S3、S3→S4、S4→写实），越往后越自然
A26: SFX_S2_EXPAND | B26: S2 | C26: 演出 | D26: 关联视图展开 | E26: S2_001 矩阵展开、连线生成 | F26: 线条依次连上的“滋滋”声 | G26: 2s | H26: 否 | I26: 1 | J26: P1
A27: SFX_SCAN | B27: S2 | C27: 演出 | D27: 扫描全局状态 | E27: S2_002 / S3_001 | F27: 扫描 sweep | G27: 1.5s | H27: 否 | I27: 1 | J27: P2 | K27: S2、S3 共用
A28: SFX_S2_PULSE_SRC | B28: S2 | C28: 引导 | D28: 脉冲源呼吸 | E28: 当前脉冲源闪烁 | F28: 带节奏的低频脉冲，引导视线 | G28: 1s | H28: 是 | I28: 1 | J28: P1
A29: SFX_S2_PULSE_RUN | B29: S2 | C29: 引导 | D29: 脉冲沿线流动 | E29: 脉冲沿下一段线路跑过去 | F29: 快速流过的电流声 | G29: 0.5–1s | H29: 否 | I29: 1 | J29: P1
A30: SFX_S2_DRAG | B30: S2 | C30: 交互 | D30: 拖拽中 | E30: 按住从脉冲源拖拽 | F30: 持续的电流流动声 | G30: 1–2s | H30: 是 | I30: 1 | J30: P0
A31: SFX_S2_NODE_LINK | B31: S2 | C31: 交互 | D31: 连上一个节点 | E31: 拖过每个节点时 | F31: 接通音，同一段内音高逐个升高 | G31: 0.2s | H31: 否 | I31: 5 | J31: P0 | K31: 每段最多 5 个节点，5 个音高做成音阶，听得出进度
A32: SFX_S2_WATER | B32: S2 | C32: 反馈 | D32: 缺水节点恢复 | E32: 缺水节点被连通恢复 | F32: 滴水 / 水流渗入，混一点电子感 | G32: 0.5–1s | H32: 否 | I32: 3 | J32: P1 | K32: 设计文档里提过“滴水声”
A33: SFX_S2_SEGMENT_DONE | B33: S2 | C33: 反馈 | D33: 一段连完 | E33: 拖到段终点 | F33: 小型完成音 | G33: 0.4s | H33: 否 | I33: 1 | J33: P1
A34: SFX_S2_WRONG | B34: S2 | C34: 反馈 | D34: 错误起点 | E34: 从非脉冲源开始拖 / 点非脉冲源 | F34: 短促的拒绝音（配合脉冲源快速闪） | G34: 0.3s | H34: 否 | I34: 1 | J34: P1
A35: SFX_S2_FRUIT_FAIL | B35: S2 | C35: 反馈 | D35: 果实无法修复 | E35: 路径走到果实时 | F35: 断开 / 失败的低音 | G35: 0.5s | H35: 否 | I35: 1 | J35: P2
A36: SFX_S2_ALL_FIXED | B36: S2 | C36: 反馈 | D36: 供给全部恢复 | E36: S2 通关 | F36: 完整的充能完成音 | G36: 1s | H36: 否 | I36: 1 | J36: P1
A37: SFX_S3_COLOR | B37: S3 | C37: 演出 | D37: RGB 模式恢复 | E37: S3_003 节点恢复颜色 | F37: 色彩展开感的上行音 | G37: 1s | H37: 否 | I37: 1 | J37: P0
A38: SFX_S3_SPATIAL | B38: S3 | C38: 演出 | D38: 空间视觉恢复 | E38: S3_004 视角解锁 | F38: 空间展开，立体声从窄变宽 | G38: 1–1.5s | H38: 否 | I38: 1 | J38: P1 | K38: 立体声制作
A39: SFX_ROTATE | B39: S3 | C39: 交互 | D39: 拖拽旋转 | E39: 拖空白处旋转网络（S3）/ 盆栽（S4） | F39: 很轻的转动 / 风声，按拖拽速度调音量 | G39: 1–2s | H39: 是 | I39: 2 | J39: P2 | K39: S3 偏电子，S4 偏自然，各一个
A40: SFX_S3_MARK | B40: S3 | C40: 交互 | D40: 标记虫子 | E40: 左键标记一个虫子节点 | F40: 锁定 / 标记音 | G40: 0.3s | H40: 否 | I40: 1 | J40: P0
...

Sheet 音乐与环境音
A1: 编号 | B1: 类型 | C1: 段落 | D1: 用途 | E1: 情绪 / 风格 | F1: 参考时长 | G1: 循环 | H1: 规格 | I1: 优先级 | J1: 备注
A2: AMB_VOID | B2: 环境音 | C2: INTRO | D2: 黑屏时的底噪 | E2: 近乎无声的低频嗡鸣，像意识深处 | F2: 30s | G2: 是 | H2: OGG/WAV 48kHz 立体声，无缝循环 | I2: P1 | J2: 开场台词全在黑屏下播，底噪很重要
A3: BGM_DIGITAL | B3: 音乐 | C3: TUT | D3: 数字空间（TUT – S1） | E3: 冷、简约、极少元素的电子氛围 | F3: 1–2min | G3: 是 | H3: 同上 | I3: P0 | J3: 建议后面几首用同一个主题旋律做分层
A4: BGM_CIRCUIT | B4: 音乐 | C4: S2 | D4: 关联 / 连线 | E4: 在 DIGITAL 基础上加入脉冲节奏 | F4: 1–2min | G4: 是 | H4: 同上 | I4: P1 | J4: 可以是 DIGITAL 的加层版本
A5: BGM_COLOR | B5: 音乐 | C5: S3 | D5: 色彩和空间恢复 | E5: 声场更宽，开始出现温暖的音色 | F5: 1–2min | G5: 是 | H5: 同上 | I5: P1
A6: BGM_AWAKEN | B6: 音乐 | C6: S4 | D6: 触觉恢复，逐步写实 | E6: 电子逐渐加入自然 / 原声乐器（钢琴、吉他、弦乐） | F6: 1–2min | G6: 是 | H6: 同上 | I6: P0 | J6: 随写实度 3 档逐层加入乐器
A7: AMB_DIGITAL | B7: 环境音 | C7: TUT | D7: 数字空间环境（TUT – S3） | E7: 极轻的电流、数据流 | F7: 30s–1min | G7: 是 | H7: 同上 | I7: P2 | J7: 可选
A8: AMB_BALCONY | B8: 环境音 | C8: S4 | D8: 真实阳台（S4 后段 – PICK） | E8: 风声、远处鸟鸣、树叶沙沙、远处城市 | F8: 1min | G8: 是 | H8: 同上 | I8: P0 | J8: S4 写实度提高后淡入
A9: BGM_PICK | B9: 音乐 | C9: PICK | D9: 采摘彩椒 | E9: 温暖、明亮、留白多，不盖过环境音 | F9: 1min | G9: 是 | H9: 同上 | I9: P1
A10: STING_STAGE_CLEAR | B10: 短音乐 | C10: 通用 | D10: 每关结束 | E10: 2–3s 短乐句，每关同旋律不同配器 | F10: 2–3s | G10: 否 | H10: 同上 | I10: P2

Sheet 视频音轨
A1: 视频 | B1: 段落 | C1: 参考时长 | D1: 画面内容 | E1: 声音需求 | F1: 待确认
A2: V_INTRO | B2: INTRO | C2: 10–20s | D2: 黑暗中有一道亮起的曙光，随着声音波动 | E2: 低频底噪 → 曙光亮起的上行音色；“声音波动”可以用亲切的声音的呼吸声 | F2: 声音波动是否就是“嗨，你醒了”的波形
A3: V_TASTE | B3: PICK | C3: 15–30s | D3: 第一人称在阳台摘彩椒、端详、咬一口 | E3: 阳台环境、正午的耳鸣 / 眩晕感、咬彩椒 | F3: 台词表里已经没有品尝视频这段，是否还要做
A4: V_OUTRO | B4: OUTRO | C4: 60–120s | D4: 回忆 → 办公室 → agent 接管 → 画面退化 → 医院 → 白光 → 快速回放 S1–S4 → 睁眼 | E4: 办公室（键盘、通知音堆叠）→ 通知越来越密、失真 → 数字退化噪声 → 医院心电监护 → 白光（全频渐强后静音）→ 回放（复用 S1–S4 关键音效）→ 睁眼（呼吸 + 阳台环境）；需要一首结尾配乐 | F4: 结尾配乐建议用游戏主题旋律的完整版
